Workbook

Sheet User Segmentation
A1: Generation | B1: Adoption Rate (U.S. 2024-25) | C1: Usage Frequency (Weekly+) | D1: Late Payment Incidence | E1: Regret After Use | J1: Revenue Source | K1: Typical Share
A2: Gen Z (18-28) | B2: 38% - 44% | C2: 0.4 | D2: 39% - 51% | E2: 27% - 64% | J2: Merchant fees | K2: 60–80%
A3: Millennials (29-44) | B3: 37% - 48% | C3: 0.28 | D3: 0.35 | E3: 30% - 57% | J3: Consumer interest | K3: 10–30%
A4: Gen X (45-60) | B4: 28% - 29% | C4: 0.1 | D4: 0.17 | E4: 22% - 37% | J4: Late fees | K4: 5–10%
A5: Baby Boomers (61-79) | B5: 13% - 21% | C5: 0.09 | D5: 0.11 | E5: 18% - 20% | J5: Interchange + other | K5: 5–15%
A15: Generation | B15: % BNPL Users
A16: Gen Z | B16: 44
A17: Millenials | B17: 48
A18: Gen X | B18: 31
A19: Baby Boomers | B19: 13
A21: Income Bracket | B21: % BNPL Users
A22: <50,000 | B22: 31
A23: 50,000-1,00,000 | B23: 32
A24: >1,00,000 | B24: 31
A27: Generation | B27: <50,000 | C27: 50,000-1,00,000 | D27: >1,00,000
A28: Gen Z | B28: 58 | C28: 32 | D28: 10
A29: Millenials | B29: 34 | C29: 41 | D29: 25
A30: Gen X | B30: 24 | C30: 39 | D30: 37
A31: Baby Boomers | B31: 42 | C31: 33 | D31: 25
A33: Generation | B33: Adjustment Factor
A34: Gen Z | B34: 1.6923077
A35: Millenial | B35: 1.7777778
A36: Gen X | B36: 1.2916667
A37: Baby Boomers | B37: 0.56521739
A39: Income Bracket | B39: <50,000 | C39: 50,000-1,00,000 | D39: >1,00,000
A40: Adjustment Factor | B40: 0.57407407 | C40: 1.1851852 | D40: 1.6315789
A43: What % of Gen uses BNPL services | H43: Column1 | I43: Column2
A44: Generation | B44: # Population (in M) | C44: Adoption Rate | D44: Weight | E44: Portfoliio Comp | F44: # of BNPL Users (in M) | H44: US Population (in M) | I44: 345
A45: Gen Z | B45: 71 | C45: 0.45 | D45: =GenSegment[[#This Row],[Adoption Rate ]]*GenSegment[[#This Row],['# Population (in M)]]/SUM(GenSegment['# Population (in M)]) -> 0.11576087 | E45: =GenSegment[[#This Row],[Weight]]/SUM(GenSegment[Weight]) -> 0.31188989 | F45: =$I$46*GenSegment[[#This Row],[Portfoliio Comp]] -> 16.140302 | H45: % of BNPL Users | I45: 0.15
A46: Millenial | B46: 74 | C46: 0.51 | D46: =GenSegment[[#This Row],[Adoption Rate ]]*GenSegment[[#This Row],['# Population (in M)]]/SUM(GenSegment['# Population (in M)]) -> 0.13673913 | E46: =GenSegment[[#This Row],[Weight]]/SUM(GenSegment[Weight]) -> 0.36841078 | F46: =$I$46*GenSegment[[#This Row],[Portfoliio Comp]] -> 19.065258 | H46: # of BNPL Users (in M) | I46: =I45*I44 -> 51.75
A47: Gen X | B47: 65.5 | C47: 0.32 | D47: =GenSegment[[#This Row],[Adoption Rate ]]*GenSegment[[#This Row],['# Population (in M)]]/SUM(GenSegment['# Population (in M)]) -> 0.075942029 | E47: =GenSegment[[#This Row],[Weight]]/SUM(GenSegment[Weight]) -> 0.20460758 | F47: =$I$46*GenSegment[[#This Row],[Portfoliio Comp]] -> 10.588442 | H47: # Total Loans (in M) | I47: 335.8
A48: Baby Boomer | B48: 65.5 | C48: 0.18 | D48: =GenSegment[[#This Row],[Adoption Rate ]]*GenSegment[[#This Row],['# Population (in M)]]/SUM(GenSegment['# Population (in M)]) -> 0.042717391 | E48: =GenSegment[[#This Row],[Weight]]/SUM(GenSegment[Weight]) -> 0.11509176 | F48: =$I$46*GenSegment[[#This Row],[Portfoliio Comp]] -> 5.9559986 | H48: Avg Loan per User | I48: =I47/I46 -> 6.4888889
H49: Avg MDR Rate | I49: =(5%+Dashboard!$K$25/10000) -> 0.05
H50: Avg Ticket Size | I50: ='Portfolio Metrics'!B4 -> 143.89084
H51: US Industry Revenue (in M) | I51: =SUMPRODUCT(ARPU_Table[[Deep Subprime]:[Super Prime]],Portfolio_Num[[Deep Subprime]:[Super Prime]]) -> 2416.8601
A52: What % of Income Bracket uses BNPL services
A53: Income Bracket | B53: Percentage of Population | C53: # Population (in M) | D53: Adoption Rate | E53: Weight | F53: Portfolio Comp | G53: # of BNPL Users (in M)
A54: <50,000 | B54: 0.54 | C54: =239.1*IncomeSegment[[#This Row],[Percentage of Population]] -> 129.114 | D54: 0.31 | E54: =IncomeSegment[[#This Row],[Adoption Rate]]*IncomeSegment[[#This Row],[Percentage of Population]] -> 0.1674 | F54: =IncomeSegment[[#This Row],[Weight]]/SUM(IncomeSegment[Weight]) -> 0.52182045 | G54: =$I$46*IncomeSegment[[#This Row],[Portfolio Comp]] -> 27.004208
A55: 50,000-1,00,000 | B55: 0.27 | C55: =239.1*IncomeSegment[[#This Row],[Percentage of Population]] -> 64.557 | D55: 0.35 | E55: =IncomeSegment[[#This Row],[Adoption Rate]]*IncomeSegment[[#This Row],[Percentage of Population]] -> 0.0945 | F55: =IncomeSegment[[#This Row],[Weight]]/SUM(IncomeSegment[Weight]) -> 0.29457606 | G55: =$I$46*IncomeSegment[[#This Row],[Portfolio Comp]] -> 15.244311
A56: >1,00,000 | B56: 0.19 | C56: =239.1*IncomeSegment[[#This Row],[Percentage of Population]] -> 45.429 | D56: 0.31 | E56: =IncomeSegment[[#This Row],[Adoption Rate]]*IncomeSegment[[#This Row],[Percentage of Population]] -> 0.0589 | F56: =IncomeSegment[[#This Row],[Weight]]/SUM(IncomeSegment[Weight]) -> 0.18360349 | G56: =$I$46*IncomeSegment[[#This Row],[Portfolio Comp]] -> 9.5014807
...

Sheet Default Rates
A1: Credit Category | B1: Credit Score
A2: Deep Subprime | B2: <580
A3: Subprime | B3: 580-619 | I3: Credit Category | J3: BNPL Loan Originations
A4: Near Prime | B4: 620-659 | I4: No Score | J4: 0.039
A5: Prime | B5: 660-719 | I5: Deep Subprime | J5: 0.45
A6: Super Prime | B6: >720 | I6: Subprime | J6: 0.16
I7: Near Prime | J7: 0.127
I8: Prime | J8: 0.132
A9: Credit Category | B9: # BNPL User Count | C9: BNPL Loan Originations | D9: BNPL Default Rates | I9: Super Prime | J9: 0.091
A10: No Score | B10: N/A | C10: 0.039 | D10: 0.041
A11: Deep Subprime | B11: =SUM(IncomexCredit_Num[Deep Subprime]) -> 11.97606 | C11: 0.45 | D11: 0.035
A12: Subprime | B12: =SUM(IncomexCredit_Num[Subprime]) -> 11.897983 | C12: 0.16 | D12: 0.011
A13: Near Prime | B13: =SUM(IncomexCredit_Num[Near Prime]) -> 9.1919163 | C13: 0.127 | D13: 0.008
A14: Prime | B14: =SUM(IncomexCredit_Num[Prime]) -> 10.241757 | C14: 0.132 | D14: 0.007
A15: Super Prime | B15: =SUM(IncomexCredit_Num[Super Prime]) -> 8.2522537 | C15: 0.091 | D15: 0.008
A17: What % of an Income Bracket lies in what Credit Category?
A18: Income Bracket | B18: Deep Subprime | C18: Subprime | D18: Near Prime | E18: Prime | F18: Super Prime | I18: Income Bracket | J18: # of BNPL Users (in M)
A19: <50,000 | B19: 0.38 | C19: 0.32 | D19: 0.15 | E19: 0.11 | F19: 0.04 | I19: <50,000 | J19: {='User Segmentation'!G54:G56} -> 27.004208
A20: 50,000-1,00,000 | B20: 0.1 | C20: 0.17 | D20: 0.25 | E20: 0.29 | F20: 0.19 | I20: 50,000-1,00,000 | J20: 15.244311
A21: >1,00,000 | B21: 0.02 | C21: 0.07 | D21: 0.14 | E21: 0.3 | F21: 0.45 | I21: >1,00,000 | J21: 9.5014807
A23: Income Bracket | B23: Deep Subprime | C23: Subprime | D23: Near Prime | E23: Prime | F23: Super Prime
A24: <50,000 | B24: =B19*$J19 -> 10.261599 | C24: =C19*$J19 -> 8.6413466 | D24: =D19*$J19 -> 4.0506312 | E24: =E19*$J19 -> 2.9704629 | F24: =F19*$J19 -> 1.0801683
A25: 50,000-1,00,000 | B25: =B20*$J20 -> 1.5244311 | C25: =C20*$J20 -> 2.5915329 | D25: =D20*$J20 -> 3.8110778 | E25: =E20*$J20 -> 4.4208502 | F25: =F20*$J20 -> 2.8964191
A26: >1,00,000 | B26: =B21*$J21 -> 0.19002961 | C26: =C21*$J21 -> 0.66510365 | D26: =D21*$J21 -> 1.3302073 | E26: =E21*$J21 -> 2.8504442 | F26: =F21*$J21 -> 4.2756663
A28: Default Rates by Income Brackets
A29: Income Bracket | B29: Default Rate
A30: <50,000 | B30: =$B19*$D$11+$C19*$D$12+$D19*$D$13+$E19*$D$14+$F19*$D$15 -> 0.01911
A31: 50,000-1,00,000 | B31: =$B20*$D$11+$C20*$D$12+$D20*$D$13+$E20*$D$14+$F20*$D$15 -> 0.01092
A32: >1,00,000 | B32: =$B21*$D$11+$C21*$D$12+$D21*$D$13+$E21*$D$14+$F21*$D$15 -> 0.00829
A34: What % of a Generation lies in what Credit Category?
A35: Generation | B35: Deep Subprime | C35: Subprime | D35: Near Prime | E35: Prime | F35: Super Prime
A36: Gen Z | B36: ='User Segmentation'!$B60*'Default Rates'!B$19+'User Segmentation'!$C60*'Default Rates'!B$20+'User Segmentation'!$D60*'Default Rates'!B$21 -> 0.278 | C36: ='User Segmentation'!$B60*'Default Rates'!C$19+'User Segmentation'!$C60*'Default Rates'!C$20+'User Segmentation'!$D60*'Default Rates'!C$21+0.0292 -> 0.2917 | D36: ='User Segmentation'!$B60*'Default Rates'!D$19+'User Segmentation'!$C60*'Default Rates'!D$20+'User Segmentation'!$D60*'Default Rates'!D$21+0.05005 -> 0.22955 | E36: =('User Segmentation'!$B60*'Default Rates'!E$19+'User Segmentation'!$C60*'Default Rates'!E$20+'User Segmentation'!$D60*'Default Rates'!E$21)*0.75 -> 0.130125 | F36: =('User Segmentation'!$B60*'Default Rates'!F$19+'User Segmentation'!$C60*'Default Rates'!F$20+'User Segmentation'!$D60*'Default Rates'!F$21)*0.75 -> 0.079125
A37: Millenial | B37: ='User Segmentation'!$B61*'Default Rates'!B$19+'User Segmentation'!$C61*'Default Rates'!B$20+'User Segmentation'!$D61*'Default Rates'!B$21 -> 0.15 | C37: ='User Segmentation'!$B61*'Default Rates'!C$19+'User Segmentation'!$C61*'Default Rates'!C$20+'User Segmentation'!$D61*'Default Rates'!C$21 -> 0.1825 | D37: ='User Segmentation'!$B61*'Default Rates'!D$19+'User Segmentation'!$C61*'Default Rates'!D$20+'User Segmentation'!$D61*'Default Rates'!D$21 -> 0.1975 | E37: ='User Segmentation'!$B61*'Default Rates'!E$19+'User Segmentation'!$C61*'Default Rates'!E$20+'User Segmentation'!$D61*'Default Rates'!E$21 -> 0.2475 | F37: ='User Segmentation'!$B61*'Default Rates'!F$19+'User Segmentation'!$C61*'Default Rates'!F$20+'User Segmentation'!$D61*'Default Rates'!F$21 -> 0.2175
A38: Gen X | B38: ='User Segmentation'!$B62*'Default Rates'!B$19+'User Segmentation'!$C62*'Default Rates'!B$20+'User Segmentation'!$D62*'Default Rates'!B$21 -> 0.118 | C38: ='User Segmentation'!$B62*'Default Rates'!C$19+'User Segmentation'!$C62*'Default Rates'!C$20+'User Segmentation'!$D62*'Default Rates'!C$21 -> 0.1625 | D38: ='User Segmentation'!$B62*'Default Rates'!D$19+'User Segmentation'!$C62*'Default Rates'!D$20+'User Segmentation'!$D62*'Default Rates'!D$21 -> 0.202 | E38: ='User Segmentation'!$B62*'Default Rates'!E$19+'User Segmentation'!$C62*'Default Rates'!E$20+'User Segmentation'!$D62*'Default Rates'!E$21 -> 0.266 | F38: ='User Segmentation'!$B62*'Default Rates'!F$19+'User Segmentation'!$C62*'Default Rates'!F$20+'User Segmentation'!$D62*'Default Rates'!F$21 -> 0.2455
A39: Baby Boomer | B39: ='User Segmentation'!$B63*'Default Rates'!B$19+'User Segmentation'!$C63*'Default Rates'!B$20+'User Segmentation'!$D63*'Default Rates'!B$21 -> 0.168 | C39: ='User Segmentation'!$B63*'Default Rates'!C$19+'User Segmentation'!$C63*'Default Rates'!C$20+'User Segmentation'!$D63*'Default Rates'!C$21 -> 0.195 | D39: ='User Segmentation'!$B63*'Default Rates'!D$19+'User Segmentation'!$C63*'Default Rates'!D$20+'User Segmentation'!$D63*'Default Rates'!D$21 -> 0.198 | E39: ='User Segmentation'!$B63*'Default Rates'!E$19+'User Segmentation'!$C63*'Default Rates'!E$20+'User Segmentation'!$D63*'Default Rates'!E$21 -> 0.238 | F39: ='User Segmentation'!$B63*'Default Rates'!F$19+'User Segmentation'!$C63*'Default Rates'!F$20+'User Segmentation'!$D63*'Default Rates'!F$21 -> 0.197
A42: Default Rates by Generation
A43: Generation | B43: Default Rates
A44: Gen Z | B44: ='User Segmentation'!B60*'Default Rates'!B58+'User Segmentation'!C60*'Default Rates'!C58+'User Segmentation'!D60*'Default Rates'!D58 -> 0.01968632
A45: Millenial | B45: ='User Segmentation'!B61*'Default Rates'!B59+'User Segmentation'!C61*'Default Rates'!C59+'User Segmentation'!D61*'Default Rates'!D59 -> 0.012658075
A46: Gen X | B46: ='User Segmentation'!B62*'Default Rates'!B60+'User Segmentation'!C62*'Default Rates'!C60+'User Segmentation'!D62*'Default Rates'!D60 -> 0.0113595
...

Sheet Portfolio x PD x Loan Count
A1: Generation | B1: Income Bracket | C1: Deep Subprime | D1: Sub Prime | E1: Near Prime | F1: Prime | G1: Super Prime
A2: Gen Z | B2: <50,000 | C2: ='User Segmentation'!$B60*'Default Rates'!B19 -> 0.247 | D2: ='User Segmentation'!$B60*'Default Rates'!C19 -> 0.208 | E2: ='User Segmentation'!$B60*'Default Rates'!D19 -> 0.0975 | F2: ='User Segmentation'!$B60*'Default Rates'!E19 -> 0.0715 | G2: ='User Segmentation'!$B60*'Default Rates'!F19 -> 0.026
A3: Gen Z | B3: 50,000-1,00,000 | C3: ='User Segmentation'!$C60*'Default Rates'!B20 -> 0.03 | D3: ='User Segmentation'!$C60*'Default Rates'!C20 -> 0.051 | E3: ='User Segmentation'!$C60*'Default Rates'!D20 -> 0.075 | F3: ='User Segmentation'!$C60*'Default Rates'!E20 -> 0.087 | G3: ='User Segmentation'!$C60*'Default Rates'!F20 -> 0.057
A4: Gen Z | B4: >1,00,000 | C4: ='User Segmentation'!$D60*'Default Rates'!B21 -> 0.001 | D4: ='User Segmentation'!$D60*'Default Rates'!C21 -> 0.0035 | E4: ='User Segmentation'!$D60*'Default Rates'!D21 -> 0.007 | F4: ='User Segmentation'!$D60*'Default Rates'!E21 -> 0.015 | G4: ='User Segmentation'!$D60*'Default Rates'!F21 -> 0.0225
A5: Millenial | B5: <50,000 | C5: ='User Segmentation'!$B61*'Default Rates'!B19 -> 0.095 | D5: ='User Segmentation'!$B61*'Default Rates'!C19 -> 0.08 | E5: ='User Segmentation'!$B61*'Default Rates'!D19 -> 0.0375 | F5: ='User Segmentation'!$B61*'Default Rates'!E19 -> 0.0275 | G5: ='User Segmentation'!$B61*'Default Rates'!F19 -> 0.01
A6: Millenial | B6: 50,000-1,00,000 | C6: ='User Segmentation'!$C61*'Default Rates'!B20 -> 0.05 | D6: ='User Segmentation'!$C61*'Default Rates'!C20 -> 0.085 | E6: ='User Segmentation'!$C61*'Default Rates'!D20 -> 0.125 | F6: ='User Segmentation'!$C61*'Default Rates'!E20 -> 0.145 | G6: ='User Segmentation'!$C61*'Default Rates'!F20 -> 0.095
A7: Millenial | B7: >1,00,000 | C7: ='User Segmentation'!$D61*'Default Rates'!B21 -> 0.005 | D7: ='User Segmentation'!$D61*'Default Rates'!C21 -> 0.0175 | E7: ='User Segmentation'!$D61*'Default Rates'!D21 -> 0.035 | F7: ='User Segmentation'!$D61*'Default Rates'!E21 -> 0.075 | G7: ='User Segmentation'!$D61*'Default Rates'!F21 -> 0.1125
A8: Gen X | B8: <50,000 | C8: ='User Segmentation'!$B62*'Default Rates'!B19 -> 0.057 | D8: ='User Segmentation'!$B62*'Default Rates'!C19 -> 0.048 | E8: ='User Segmentation'!$B62*'Default Rates'!D19 -> 0.0225 | F8: ='User Segmentation'!$B62*'Default Rates'!E19 -> 0.0165 | G8: ='User Segmentation'!$B62*'Default Rates'!F19 -> 0.006
A9: Gen X | B9: 50,000-1,00,000 | C9: ='User Segmentation'!$C62*'Default Rates'!B20 -> 0.055 | D9: ='User Segmentation'!$C62*'Default Rates'!C20 -> 0.0935 | E9: ='User Segmentation'!$C62*'Default Rates'!D20 -> 0.1375 | F9: ='User Segmentation'!$C62*'Default Rates'!E20 -> 0.1595 | G9: ='User Segmentation'!$C62*'Default Rates'!F20 -> 0.1045 | J9: Generation | K9: # of BNPL Users (in M)
A10: Gen X | B10: >1,00,000 | C10: ='User Segmentation'!$D62*'Default Rates'!B21 -> 0.006 | D10: ='User Segmentation'!$D62*'Default Rates'!C21 -> 0.021 | E10: ='User Segmentation'!$D62*'Default Rates'!D21 -> 0.042 | F10: ='User Segmentation'!$D62*'Default Rates'!E21 -> 0.09 | G10: ='User Segmentation'!$D62*'Default Rates'!F21 -> 0.135 | J10: Gen Z | K10: =SUM('User Segmentation'!B83:D83) -> 16.140302
A11: Baby Boomer | B11: <50,000 | C11: ='User Segmentation'!$B$63*'Default Rates'!B19 -> 0.114 | D11: ='User Segmentation'!$B63*'Default Rates'!C19 -> 0.096 | E11: ='User Segmentation'!$B63*'Default Rates'!D19 -> 0.045 | F11: ='User Segmentation'!$B63*'Default Rates'!E19 -> 0.033 | G11: ='User Segmentation'!$B63*'Default Rates'!F19 -> 0.012 | J11: Millenial | K11: =SUM('User Segmentation'!B84:D84) -> 19.065258
A12: Baby Boomer | B12: 50,000-1,00,000 | C12: ='User Segmentation'!$C$63*'Default Rates'!B20 -> 0.05 | D12: ='User Segmentation'!$C$63*'Default Rates'!C20 -> 0.085 | E12: ='User Segmentation'!$C$63*'Default Rates'!D20 -> 0.125 | F12: ='User Segmentation'!$C$63*'Default Rates'!E20 -> 0.145 | G12: ='User Segmentation'!$C$63*'Default Rates'!F20 -> 0.095 | J12: Gen X | K12: =SUM('User Segmentation'!B85:D85) -> 10.588442
A13: Baby Boomer | B13: >1,00,000 | C13: ='User Segmentation'!$D$63*'Default Rates'!B21 -> 0.004 | D13: ='User Segmentation'!$D$63*'Default Rates'!C21 -> 0.014 | E13: ='User Segmentation'!$D$63*'Default Rates'!D21 -> 0.028 | F13: ='User Segmentation'!$D$63*'Default Rates'!E21 -> 0.06 | G13: ='User Segmentation'!$D$63*'Default Rates'!F21 -> 0.09 | J13: Baby Boomer | K13: =SUM('User Segmentation'!B86:D86) -> 5.9559986
A16: Generation | B16: Income Bracket | C16: Deep Subprime | D16: Sub Prime | E16: Near Prime | F16: Prime | G16: Super Prime | O16: Income Bracket | P16: Sum
A17: Gen Z | B17: <50,000 | C17: =C2*$K$10 -> 3.9866545 | D17: =D2*$K$10 -> 3.3571827 | E17: =E2*$K$10 -> 1.5736794 | F17: =F2*$K$10 -> 1.1540316 | G17: =G2*$K$10 -> 0.41964784 | O17: <50k | P17: =SUM(Table40[[#This Row],[Deep Subprime]:[Super Prime]],C20:G20,C23:G23,C26:G26) -> 18.632576
A18: Gen Z | B18: 50,000-1,00,000 | C18: =C3*$K$10 -> 0.48420905 | D18: =D3*$K$10 -> 0.82315538 | E18: =E3*$K$10 -> 1.2105226 | F18: =F3*$K$10 -> 1.4042062 | G18: =G3*$K$10 -> 0.91999719 | O18: 50k-100k | P18: =SUM(Table40[[#This Row],[Deep Subprime]:[Super Prime]],C21:G21,C24:G24,C27:G27) -> 23.176362
A19: Gen Z | B19: >1,00,000 | C19: =C4*$K$10 -> 0.016140302 | D19: =D4*$K$10 -> 0.056491056 | E19: =E4*$K$10 -> 0.11298211 | F19: =F4*$K$10 -> 0.24210452 | G19: =G4*$K$10 -> 0.36315679 | O19: >100k | P19: =SUM(Table40[[#This Row],[Deep Subprime]:[Super Prime]],C22:G22,C25:G25,C28:G28) -> 9.7422406
A20: Millenial | B20: <50,000 | C20: =C5*$K$11 -> 1.8111995 | D20: =D5*$K$11 -> 1.5252206 | E20: =E5*$K$11 -> 0.71494716 | F20: =F5*$K$11 -> 0.52429459 | G20: =G5*$K$11 -> 0.19065258
A21: Millenial | B21: 50,000-1,00,000 | C21: =C6*$K$11 -> 0.95326289 | D21: =D6*$K$11 -> 1.6205469 | E21: =E6*$K$11 -> 2.3831572 | F21: =F6*$K$11 -> 2.7644624 | G21: =G6*$K$11 -> 1.8111995
A22: Millenial | B22: >1,00,000 | C22: =C7*$K$11 -> 0.095326289 | D22: =D7*$K$11 -> 0.33364201 | E22: =E7*$K$11 -> 0.66728402 | F22: =F7*$K$11 -> 1.4298943 | G22: =G7*$K$11 -> 2.1448415 | O22: Generation | P22: Sum
A23: Gen X | B23: <50,000 | C23: =C8*$K$12 -> 0.60354119 | D23: =D8*$K$12 -> 0.50824522 | E23: =E8*$K$12 -> 0.23823995 | F23: =F8*$K$12 -> 0.17470929 | G23: =G8*$K$12 -> 0.063530652 | O23: Gen Z | P23: =SUM(C31:G33) -> 19.161126
A24: Gen X | B24: 50,000-1,00,000 | C24: =C9*$K$12 -> 0.58236431 | D24: =D9*$K$12 -> 0.99001933 | E24: =E9*$K$12 -> 1.4559108 | F24: =F9*$K$12 -> 1.6888565 | G24: =G9*$K$12 -> 1.1064922 | O24: Millenial | P24: =SUM(C34:G36) -> 17.733488
A25: Gen X | B25: >1,00,000 | C25: =C10*$K$12 -> 0.063530652 | D25: =D10*$K$12 -> 0.22235728 | E25: =E10*$K$12 -> 0.44471456 | F25: =F10*$K$12 -> 0.95295978 | G25: =G10*$K$12 -> 1.4294397 | O25: Gen X | P25: =SUM(C37:G39) -> 9.1684621
A26: Baby Boomer | B26: <50,000 | C26: =C11*$K$13 -> 0.67898384 | D26: =D11*$K$13 -> 0.57177587 | E26: =E11*$K$13 -> 0.26801994 | F26: =F11*$K$13 -> 0.19654795 | G26: =G11*$K$13 -> 0.071471984 | O26: Baby Boomer | P26: =SUM(C40:G42) -> 5.6869231
A27: Baby Boomer | B27: 50,000-1,00,000 | C27: =C12*$K$13 -> 0.29779993 | D27: =D12*$K$13 -> 0.50625988 | E27: =E12*$K$13 -> 0.74449983 | F27: =F12*$K$13 -> 0.8636198 | G27: =G12*$K$13 -> 0.56581987
A28: Baby Boomer | B28: >1,00,000 | C28: =C13*$K$13 -> 0.023823995 | D28: =D13*$K$13 -> 0.083383981 | E28: =E13*$K$13 -> 0.16676796 | F28: =F13*$K$13 -> 0.35735992 | G28: =G13*$K$13 -> 0.53603988
A30: Generation | B30: Income Bracket | C30: Deep Subprime | D30: Sub Prime | E30: Near Prime | F30: Prime | G30: Super Prime | O30: Income Bracket | P30: # of BNPL Users (in M)
A31: Gen Z | B31: <50,000 | C31: =C17*$P31/$P17 -> 5.7778616 | D31: =D17*$P$31/$P$17 -> 4.8655677 | E31: =E17*$P$31/$P$17 -> 2.2807349 | F31: =F17*$P$31/$P$17 -> 1.6725389 | G31: =G17*$P$31/$P$17 -> 0.60819596 | O31: <50,000 | P31: ='User Segmentation'!G54 -> 27.004208
A32: Gen Z | B32: 50,000-1,00,000 | C32: =C18*$P32/$P18 -> 0.31848974 | D32: =D18*$P32/$P18 -> 0.54143255 | E32: =E18*$P32/$P18 -> 0.79622434 | F32: =F18*$P32/$P18 -> 0.92362024 | G32: =G18*$P32/$P18 -> 0.6051305 | O32: 50,000-1,00,000 | P32: ='User Segmentation'!G55 -> 15.244311
A33: Gen Z | B33: >1,00,000 | C33: =C19*$P33/$P19 -> 0.015741426 | D33: =D19*$P33/$P19 -> 0.055094993 | E33: =E19*$P33/$P19 -> 0.11018999 | F33: =F19*$P33/$P19 -> 0.2361214 | G33: =G19*$P33/$P19 -> 0.3541821 | O33: >1,00,000 | P33: ='User Segmentation'!G56 -> 9.5014807
A34: Millenial | B34: <50,000 | C34: =C20*$P31/$P17 -> 2.6249729 | D34: =D20*$P31/$P17 -> 2.2105035 | E34: =E20*$P31/$P17 -> 1.0361735 | F34: =F20*$P31/$P17 -> 0.75986057 | G34: =G20*$P31/$P17 -> 0.27631294
A35: Millenial | B35: 50,000-1,00,000 | C35: =C21*$P32/$P18 -> 0.6270111 | D35: =D21*$P32/$P18 -> 1.0659189 | E35: =E21*$P32/$P18 -> 1.5675277 | F35: =F21*$P32/$P18 -> 1.8183322 | G35: =G21*$P32/$P18 -> 1.1913211
A36: Millenial | B36: >1,00,000 | C36: =C22*$P33/$P19 -> 0.092970491 | D36: =D22*$P33/$P19 -> 0.32539672 | E36: =E22*$P33/$P19 -> 0.65079343 | F36: =F22*$P33/$P19 -> 1.3945574 | G36: =G22*$P33/$P19 -> 2.091836
A37: Gen X | B37: <50,000 | C37: =C23*$P31/$P17 -> 0.87471275 | D37: =D23*$P31/$P17 -> 0.73660021 | E37: =E23*$P31/$P17 -> 0.34528135 | F37: =F23*$P31/$P17 -> 0.25320632 | G37: =G23*$P31/$P17 -> 0.092075026
A38: Gen X | B38: 50,000-1,00,000 | C38: =C24*$P32/$P18 -> 0.38305161 | D38: =D24*$P32/$P18 -> 0.65118774 | E38: =E24*$P32/$P18 -> 0.95762903 | F38: =F24*$P32/$P18 -> 1.1108497 | G38: =G24*$P32/$P18 -> 0.72779806
A39: Gen X | B39: >1,00,000 | C39: =C25*$P33/$P19 -> 0.061960619 | D39: =D25*$P33/$P19 -> 0.21686217 | E39: =E25*$P33/$P19 -> 0.43372434 | F39: =F25*$P33/$P19 -> 0.92940929 | G39: =G25*$P33/$P19 -> 1.3941139
A40: Baby Boomer | B40: <50,000 | C40: =C26*$P31/$P17 -> 0.98405184 | D40: =D26*$P31/$P17 -> 0.82867524 | E40: =E26*$P31/$P17 -> 0.38844152 | F40: =F26*$P31/$P17 -> 0.28485711 | G40: =G26*$P31/$P17 -> 0.1035844
A41: Baby Boomer | B41: 50,000-1,00,000 | C41: =C27*$P32/$P18 -> 0.19587866 | D41: =D27*$P32/$P18 -> 0.33299373 | E41: =E27*$P32/$P18 -> 0.48969666 | F41: =F27*$P32/$P18 -> 0.56804813 | G41: =G27*$P32/$P18 -> 0.37216946
A42: Baby Boomer | B42: >1,00,000 | C42: =C28*$P33/$P19 -> 0.023235232 | D42: =D28*$P33/$P19 -> 0.081323313 | E42: =E28*$P33/$P19 -> 0.16264663 | F42: =F28*$P33/$P19 -> 0.34852848 | G42: =G28*$P33/$P19 -> 0.52279273
A46: # BNPL Portfolio (in M)
...

Sheet Support Tables
A1: Base ATS Values | I1: ATS Scale
A2: Generation | B2: Income Bracket | C2: Deep Subprime | D2: Sub Prime | E2: Near Prime | F2: Prime | G2: Super Prime | I2: =145/126 -> 1.1507937
A3: Gen Z | B3: <50000 | C3: 49.84 | D3: 58.91 | E3: 77.03 | F3: 99.69 | G3: 131.41
A4: Gen Z | B4: 50000-100000 | C4: 72.5 | D4: 86.09 | E4: 108.75 | F4: 145 | G4: 185
A5: Gen Z | B5: >100000 | C5: 95 | D5: 118 | E5: 158 | F5: 220 | G5: 290
A6: Millenial | B6: <50000 | C6: 63.44 | D6: 77.03 | E6: 104.22 | F6: 135.94 | G6: 168
A7: Millenial | B7: 50000-100000 | C7: 86.09 | D7: 113.28 | E7: 163.13 | F7: 218 | G7: 292
A8: Millenial | B8: >100000 | C8: 132 | D8: 182 | E8: 265 | F8: 338 | G8: 395
A9: Gen X | B9: <50000 | C9: 67.97 | D9: 81.56 | E9: 108.75 | F9: 140.47 | G9: 167.66
A10: Gen X | B10: 50000-100000 | C10: 99.69 | D10: 135.94 | E10: 199.38 | F10: 275 | G10: 360
A11: Gen X | B11: >100000 | C11: 158 | D11: 224 | E11: 328 | F11: 368 | G11: 395
A12: Baby Boomer | B12: <50000 | C12: 54.38 | D12: 67.97 | E12: 86.09 | F12: 108.75 | G12: 135.94
A13: Baby Boomer | B13: 50000-100000 | C13: 81.56 | D13: 104.22 | E13: 145 | F13: 192 | G13: 255
A14: Baby Boomer | B14: >100000 | C14: 124 | D14: 168 | E14: 245 | F14: 318 | G14: 375
A16: Average Ticket Size | I16: Expected Credit Loss (ECL)
A17: Generation | B17: Income Bracket | C17: Deep Subprime | D17: Sub Prime | E17: Near Prime | F17: Prime | G17: Super Prime | I17: Generation | J17: Income Bracket | K17: Deep Subprime | L17: Sub Prime | M17: Near Prime | N17: Prime | O17: Super Prime
A18: Gen Z | B18: <50,000 | C18: =C3*$I$2 -> 57.355556 | D18: =D3*$I$2 -> 67.793254 | E18: =E3*$I$2 -> 88.645635 | F18: =F3*$I$2 -> 114.72262 | G18: =G3*$I$2 -> 151.22579 | I18: Gen Z | J18: <50,000 | K18: =ATS_Table[[#This Row],[Deep Subprime]]*'Dynamic PD'!N3*'EAD Estimate'!$E$2*'EAD Estimate'!$F$2 -> 1.4077204 | L18: =ATS_Table[[#This Row],[Sub Prime]]*'Dynamic PD'!O3*'EAD Estimate'!$E$3*'EAD Estimate'!$F$3 -> 0.46141783 | M18: =ATS_Table[[#This Row],[Near Prime]]*'Dynamic PD'!P3*'EAD Estimate'!$E$4*'EAD Estimate'!$F$4 -> 0.40369222 | N18: =ATS_Table[[#This Row],[Prime]]*'Dynamic PD'!Q3*'EAD Estimate'!$E$5*'EAD Estimate'!$F$5 -> 0.43064003 | O18: =ATS_Table[[#This Row],[Super Prime]]*'Dynamic PD'!R3*'EAD Estimate'!$E$6*'EAD Estimate'!$F$6 -> 0.58887324
A19: Gen Z | B19: 50,000-1,00,000 | C19: =C4*$I$2 -> 83.43254 | D19: =D4*$I$2 -> 99.071825 | E19: =E4*$I$2 -> 125.14881 | F19: =F4*$I$2 -> 166.86508 | G19: =G4*$I$2 -> 212.89683 | I19: Gen Z | J19: 50,000-1,00,000 | K19: =ATS_Table[[#This Row],[Deep Subprime]]*'Dynamic PD'!N4*'EAD Estimate'!$E$2*'EAD Estimate'!$F$2 -> 2.0105156 | L19: =ATS_Table[[#This Row],[Sub Prime]]*'Dynamic PD'!O4*'EAD Estimate'!$E$3*'EAD Estimate'!$F$3 -> 0.66204747 | M19: =ATS_Table[[#This Row],[Near Prime]]*'Dynamic PD'!P4*'EAD Estimate'!$E$4*'EAD Estimate'!$F$4 -> 0.55956536 | N19: =ATS_Table[[#This Row],[Prime]]*'Dynamic PD'!Q4*'EAD Estimate'!$E$5*'EAD Estimate'!$F$5 -> 0.61498125 | O19: =ATS_Table[[#This Row],[Super Prime]]*'Dynamic PD'!R4*'EAD Estimate'!$E$6*'EAD Estimate'!$F$6 -> 0.81394714
A20: Gen Z | B20: >1,00,000 | C20: =C5*$I$2 -> 109.3254 | D20: =D5*$I$2 -> 135.79365 | E20: =E5*$I$2 -> 181.8254 | F20: =F5*$I$2 -> 253.1746 | G20: =G5*$I$2 -> 333.73016 | I20: Gen Z | J20: >1,00,000 | K20: =ATS_Table[[#This Row],[Deep Subprime]]*'Dynamic PD'!N5*'EAD Estimate'!$E$2*'EAD Estimate'!$F$2 -> 2.4393229 | L20: =ATS_Table[[#This Row],[Sub Prime]]*'Dynamic PD'!O5*'EAD Estimate'!$E$3*'EAD Estimate'!$F$3 -> 0.84022321 | M20: =ATS_Table[[#This Row],[Near Prime]]*'Dynamic PD'!P5*'EAD Estimate'!$E$4*'EAD Estimate'!$F$4 -> 0.75275714 | N20: =ATS_Table[[#This Row],[Prime]]*'Dynamic PD'!Q5*'EAD Estimate'!$E$5*'EAD Estimate'!$F$5 -> 0.86395833 | O20: =ATS_Table[[#This Row],[Super Prime]]*'Dynamic PD'!R5*'EAD Estimate'!$E$6*'EAD Estimate'!$F$6 -> 1.1814048
A21: Millenial | B21: <50,000 | C21: =C6*$I$2 -> 73.006349 | D21: =D6*$I$2 -> 88.645635 | E21: =E6*$I$2 -> 119.93571 | F21: =F6*$I$2 -> 156.43889 | G21: =G6*$I$2 -> 193.33333 | I21: Millenial | J21: <50,000 | K21: =ATS_Table[[#This Row],[Deep Subprime]]*'Dynamic PD'!N6*'EAD Estimate'!$E$2*'EAD Estimate'!$F$2 -> 1.7918496 | L21: =ATS_Table[[#This Row],[Sub Prime]]*'Dynamic PD'!O6*'EAD Estimate'!$E$3*'EAD Estimate'!$F$3 -> 0.60334435 | M21: =ATS_Table[[#This Row],[Near Prime]]*'Dynamic PD'!P6*'EAD Estimate'!$E$4*'EAD Estimate'!$F$4 -> 0.54618724 | N21: =ATS_Table[[#This Row],[Prime]]*'Dynamic PD'!Q6*'EAD Estimate'!$E$5*'EAD Estimate'!$F$5 -> 0.58723248 | O21: =ATS_Table[[#This Row],[Super Prime]]*'Dynamic PD'!R6*'EAD Estimate'!$E$6*'EAD Estimate'!$F$6 -> 0.75284
A22: Millenial | B22: 50,000-1,00,000 | C22: =C7*$I$2 -> 99.071825 | D22: =D7*$I$2 -> 130.3619 | E22: =E7*$I$2 -> 187.72897 | F22: =F7*$I$2 -> 250.87302 | G22: =G7*$I$2 -> 336.03175 | I22: Millenial | J22: 50,000-1,00,000 | K22: =ATS_Table[[#This Row],[Deep Subprime]]*'Dynamic PD'!N7*'EAD Estimate'!$E$2*'EAD Estimate'!$F$2 -> 2.2989617 | L22: =ATS_Table[[#This Row],[Sub Prime]]*'Dynamic PD'!O7*'EAD Estimate'!$E$3*'EAD Estimate'!$F$3 -> 0.83887886 | M22: =ATS_Table[[#This Row],[Near Prime]]*'Dynamic PD'!P7*'EAD Estimate'!$E$4*'EAD Estimate'!$F$4 -> 0.80828585 | N22: =ATS_Table[[#This Row],[Prime]]*'Dynamic PD'!Q7*'EAD Estimate'!$E$5*'EAD Estimate'!$F$5 -> 0.89034833 | O22: =ATS_Table[[#This Row],[Super Prime]]*'Dynamic PD'!R7*'EAD Estimate'!$E$6*'EAD Estimate'!$F$6 -> 1.2371345
A23: Millenial | B23: >1,00,000 | C23: =C8*$I$2 -> 151.90476 | D23: =D8*$I$2 -> 209.44444 | E23: =E8*$I$2 -> 304.96032 | F23: =F8*$I$2 -> 388.96825 | G23: =G8*$I$2 -> 454.56349 | I23: Millenial | J23: >1,00,000 | K23: =ATS_Table[[#This Row],[Deep Subprime]]*'Dynamic PD'!N8*'EAD Estimate'!$E$2*'EAD Estimate'!$F$2 -> 3.389375 | L23: =ATS_Table[[#This Row],[Sub Prime]]*'Dynamic PD'!O8*'EAD Estimate'!$E$3*'EAD Estimate'!$F$3 -> 1.2959375 | M23: =ATS_Table[[#This Row],[Near Prime]]*'Dynamic PD'!P8*'EAD Estimate'!$E$4*'EAD Estimate'!$F$4 -> 1.2625357 | N23: =ATS_Table[[#This Row],[Prime]]*'Dynamic PD'!Q8*'EAD Estimate'!$E$5*'EAD Estimate'!$F$5 -> 1.3273542 | O23: =ATS_Table[[#This Row],[Super Prime]]*'Dynamic PD'!R8*'EAD Estimate'!$E$6*'EAD Estimate'!$F$6 -> 1.6091548
A24: Gen X | B24: <50,000 | C24: =C9*$I$2 -> 78.219444 | D24: =D9*$I$2 -> 93.85873 | E24: =E9*$I$2 -> 125.14881 | F24: =F9*$I$2 -> 161.65198 | G24: =G9*$I$2 -> 192.94206 | I24: Gen X | J24: <50,000 | K24: =ATS_Table[[#This Row],[Deep Subprime]]*'Dynamic PD'!N9*'EAD Estimate'!$E$2*'EAD Estimate'!$F$2 -> 1.7452714 | L24: =ATS_Table[[#This Row],[Sub Prime]]*'Dynamic PD'!O9*'EAD Estimate'!$E$3*'EAD Estimate'!$F$3 -> 0.58075089 | M24: =ATS_Table[[#This Row],[Near Prime]]*'Dynamic PD'!P9*'EAD Estimate'!$E$4*'EAD Estimate'!$F$4 -> 0.51811607 | N24: =ATS_Table[[#This Row],[Prime]]*'Dynamic PD'!Q9*'EAD Estimate'!$E$5*'EAD Estimate'!$F$5 -> 0.5516374 | O24: =ATS_Table[[#This Row],[Super Prime]]*'Dynamic PD'!R9*'EAD Estimate'!$E$6*'EAD Estimate'!$F$6 -> 0.6830149
A25: Gen X | B25: 50,000-1,00,000 | C25: =C10*$I$2 -> 114.72262 | D25: =D10*$I$2 -> 156.43889 | E25: =E10*$I$2 -> 229.44524 | F25: =F10*$I$2 -> 316.46825 | G25: =G10*$I$2 -> 414.28571 | I25: Gen X | J25: 50,000-1,00,000 | K25: =ATS_Table[[#This Row],[Deep Subprime]]*'Dynamic PD'!N10*'EAD Estimate'!$E$2*'EAD Estimate'!$F$2 -> 2.5597484 | L25: =ATS_Table[[#This Row],[Sub Prime]]*'Dynamic PD'!O10*'EAD Estimate'!$E$3*'EAD Estimate'!$F$3 -> 0.96796562 | M25: =ATS_Table[[#This Row],[Near Prime]]*'Dynamic PD'!P10*'EAD Estimate'!$E$4*'EAD Estimate'!$F$4 -> 0.94990329 | N25: =ATS_Table[[#This Row],[Prime]]*'Dynamic PD'!Q10*'EAD Estimate'!$E$5*'EAD Estimate'!$F$5 -> 1.0799479 | O25: =ATS_Table[[#This Row],[Super Prime]]*'Dynamic PD'!R10*'EAD Estimate'!$E$6*'EAD Estimate'!$F$6 -> 1.4665714
A26: Gen X | B26: >1,00,000 | C26: =C11*$I$2 -> 181.8254 | D26: =D11*$I$2 -> 257.77778 | E26: =E11*$I$2 -> 377.46032 | F26: =F11*$I$2 -> 423.49206 | G26: =G11*$I$2 -> 454.56349 | I26: Gen X | J26: >1,00,000 | K26: =ATS_Table[[#This Row],[Deep Subprime]]*'Dynamic PD'!N11*'EAD Estimate'!$E$2*'EAD Estimate'!$F$2 -> 4.0569792 | L26: =ATS_Table[[#This Row],[Sub Prime]]*'Dynamic PD'!O11*'EAD Estimate'!$E$3*'EAD Estimate'!$F$3 -> 1.595 | M26: =ATS_Table[[#This Row],[Near Prime]]*'Dynamic PD'!P11*'EAD Estimate'!$E$4*'EAD Estimate'!$F$4 -> 1.5626857 | N26: =ATS_Table[[#This Row],[Prime]]*'Dynamic PD'!Q11*'EAD Estimate'!$E$5*'EAD Estimate'!$F$5 -> 1.4451667 | O26: =ATS_Table[[#This Row],[Super Prime]]*'Dynamic PD'!R11*'EAD Estimate'!$E$6*'EAD Estimate'!$F$6 -> 1.6091548
A27: Baby Boomer | B27: <50,000 | C27: =C12*$I$2 -> 62.580159 | D27: =D12*$I$2 -> 78.219444 | E27: =E12*$I$2 -> 99.071825 | F27: =F12*$I$2 -> 125.14881 | G27: =G12*$I$2 -> 156.43889 | I27: Baby Boomer | J27: <50,000 | K27: =ATS_Table[[#This Row],[Deep Subprime]]*'Dynamic PD'!N12*'EAD Estimate'!$E$2*'EAD Estimate'!$F$2 -> 1.4661358 | L27: =ATS_Table[[#This Row],[Sub Prime]]*'Dynamic PD'!O12*'EAD Estimate'!$E$3*'EAD Estimate'!$F$3 -> 0.50818195 | M27: =ATS_Table[[#This Row],[Near Prime]]*'Dynamic PD'!P12*'EAD Estimate'!$E$4*'EAD Estimate'!$F$4 -> 0.43066522 | N27: =ATS_Table[[#This Row],[Prime]]*'Dynamic PD'!Q12*'EAD Estimate'!$E$5*'EAD Estimate'!$F$5 -> 0.44842383 | O27: =ATS_Table[[#This Row],[Super Prime]]*'Dynamic PD'!R12*'EAD Estimate'!$E$6*'EAD Estimate'!$F$6 -> 0.58148335
A28: Baby Boomer | B28: 50,000-1,00,000 | C28: =C13*$I$2 -> 93.85873 | D28: =D13*$I$2 -> 119.93571 | E28: =E13*$I$2 -> 166.86508 | F28: =F13*$I$2 -> 220.95238 | G28: =G13*$I$2 -> 293.45238 | I28: Baby Boomer | J28: 50,000-1,00,000 | K28: =ATS_Table[[#This Row],[Deep Subprime]]*'Dynamic PD'!N13*'EAD Estimate'!$E$2*'EAD Estimate'!$F$2 -> 2.0942229 | L28: =ATS_Table[[#This Row],[Sub Prime]]*'Dynamic PD'!O13*'EAD Estimate'!$E$3*'EAD Estimate'!$F$3 -> 0.74210223 | M28: =ATS_Table[[#This Row],[Near Prime]]*'Dynamic PD'!P13*'EAD Estimate'!$E$4*'EAD Estimate'!$F$4 -> 0.69082143 | N28: =ATS_Table[[#This Row],[Prime]]*'Dynamic PD'!Q13*'EAD Estimate'!$E$5*'EAD Estimate'!$F$5 -> 0.754 | O28: =ATS_Table[[#This Row],[Super Prime]]*'Dynamic PD'!R13*'EAD Estimate'!$E$6*'EAD Estimate'!$F$6 -> 1.0388214
A29: Baby Boomer | B29: >1,00,000 | C29: =C14*$I$2 -> 142.69841 | D29: =D14*$I$2 -> 193.33333 | E29: =E14*$I$2 -> 281.94444 | F29: =F14*$I$2 -> 365.95238 | G29: =G14*$I$2 -> 431.54762 | I29: Baby Boomer | J29: >1,00,000 | K29: =ATS_Table[[#This Row],[Deep Subprime]]*'Dynamic PD'!N14*'EAD Estimate'!$E$2*'EAD Estimate'!$F$2 -> 3.1839583 | L29: =ATS_Table[[#This Row],[Sub Prime]]*'Dynamic PD'!O14*'EAD Estimate'!$E$3*'EAD Estimate'!$F$3 -> 1.19625 | M29: =ATS_Table[[#This Row],[Near Prime]]*'Dynamic PD'!P14*'EAD Estimate'!$E$4*'EAD Estimate'!$F$4 -> 1.16725 | N29: =ATS_Table[[#This Row],[Prime]]*'Dynamic PD'!Q14*'EAD Estimate'!$E$5*'EAD Estimate'!$F$5 -> 1.2488125 | O29: =ATS_Table[[#This Row],[Super Prime]]*'Dynamic PD'!R14*'EAD Estimate'!$E$6*'EAD Estimate'!$F$6 -> 1.5276786
A31: Average Revenue Per User | I31: Funding Cost (FC)
A32: Generation | B32: Column1 | C32: Deep Subprime | D32: Sub Prime | E32: Near Prime | F32: Prime | G32: Super Prime | I32: Generation | J32: Income Bracket | K32: Deep Subprime | L32: Sub Prime | M32: Near Prime | N32: Prime | O32: Super Prime
A33: Gen Z | B33: <50,000 | C33: =C18*'Portfolio x PD x Loan Count'!C132*'User Segmentation'!$I$49/'Portfolio x PD x Loan Count'!C64 -> 37.71548 | D33: =D18*'Portfolio x PD x Loan Count'!D132*'User Segmentation'!$I$49/'Portfolio x PD x Loan Count'!D64 -> 15.945047 | E33: =E18*'Portfolio x PD x Loan Count'!E132*'User Segmentation'!$I$49/'Portfolio x PD x Loan Count'!E64 -> 21.426557 | F33: =F18*'Portfolio x PD x Loan Count'!F132*'User Segmentation'!$I$49/'Portfolio x PD x Loan Count'!F64 -> 25.864405 | G33: =G18*'Portfolio x PD x Loan Count'!G132*'User Segmentation'!$I$49/'Portfolio x PD x Loan Count'!G64 -> 29.17635 | I33: Gen Z | J33: <50,000 | K33: {=C18*Dynamic_Row_Table[[Funding Rate]:[Funding Rate]]*Dynamic_Row_Table[[Tenure (in months)]:[Tenure (in months)]]/12} -> 0.68109722 | L33: {=D18*Dynamic_Row_Table[[Funding Rate]:[Funding Rate]]*Dynamic_Row_Table[[Tenure (in months)]:[Tenure (in months)]]/12} -> 0.80504489 | M33: {=E18*Dynamic_Row_Table[[Funding Rate]:[Funding Rate]]*Dynamic_Row_Table[[Tenure (in months)]:[Tenure (in months)]]/12} -> 1.0526669 | N33: {=F18*Dynamic_Row_Table[[Funding Rate]:[Funding Rate]]*Dynamic_Row_Table[[Tenure (in months)]:[Tenure (in months)]]/12} -> 1.3623311 | O33: {=G18*Dynamic_Row_Table[[Funding Rate]:[Funding Rate]]*Dynamic_Row_Table[[Tenure (in months)]:[Tenure (in months)]]/12} -> 1.7958063
A34: Gen Z | B34: 50,000-1,00,000 | C34: =C19*'Portfolio x PD x Loan Count'!C133*'User Segmentation'!$I$49/'Portfolio x PD x Loan Count'!C65 -> 54.863008 | D34: =D19*'Portfolio x PD x Loan Count'!D133*'User Segmentation'!$I$49/'Portfolio x PD x Loan Count'!D65 -> 23.301802 | E34: =E19*'Portfolio x PD x Loan Count'!E133*'User Segmentation'!$I$49/'Portfolio x PD x Loan Count'!E65 -> 30.249747 | F34: =F19*'Portfolio x PD x Loan Count'!F133*'User Segmentation'!$I$49/'Portfolio x PD x Loan Count'!F65 -> 37.620009 | G34: =G19*'Portfolio x PD x Loan Count'!G133*'User Segmentation'!$I$49/'Portfolio x PD x Loan Count'!G65 -> 41.074688 | I34: Gen Z | J34: 50,000-1,00,000 | K34: {=C19*Dynamic_Row_Table[[Funding Rate]:[Funding Rate]]*Dynamic_Row_Table[[Tenure (in months)]:[Tenure (in months)]]/12} -> 0.99076141 | L34: {=D19*Dynamic_Row_Table[[Funding Rate]:[Funding Rate]]*Dynamic_Row_Table[[Tenure (in months)]:[Tenure (in months)]]/12} -> 1.1764779 | M34: {=E19*Dynamic_Row_Table[[Funding Rate]:[Funding Rate]]*Dynamic_Row_Table[[Tenure (in months)]:[Tenure (in months)]]/12} -> 1.4861421 | N34: {=F19*Dynamic_Row_Table[[Funding Rate]:[Funding Rate]]*Dynamic_Row_Table[[Tenure (in months)]:[Tenure (in months)]]/12} -> 1.9815228 | O34: {=G19*Dynamic_Row_Table[[Funding Rate]:[Funding Rate]]*Dynamic_Row_Table[[Tenure (in months)]:[Tenure (in months)]]/12} -> 2.5281498
A35: Gen Z | B35: >1,00,000 | C35: =C20*'Portfolio x PD x Loan Count'!C134*'User Segmentation'!$I$49/'Portfolio x PD x Loan Count'!C66 -> 71.889458 | D35: =D20*'Portfolio x PD x Loan Count'!D134*'User Segmentation'!$I$49/'Portfolio x PD x Loan Count'!D66 -> 31.938815 | E35: =E20*'Portfolio x PD x Loan Count'!E134*'User Segmentation'!$I$49/'Portfolio x PD x Loan Count'!E66 -> 43.949058 | F35: =F20*'Portfolio x PD x Loan Count'!F134*'User Segmentation'!$I$49/'Portfolio x PD x Loan Count'!F66 -> 57.078635 | G35: =G20*'Portfolio x PD x Loan Count'!G134*'User Segmentation'!$I$49/'Portfolio x PD x Loan Count'!G66 -> 64.387348 | I35: Gen Z | J35: >1,00,000 | K35: {=C20*Dynamic_Row_Table[[Funding Rate]:[Funding Rate]]*Dynamic_Row_Table[[Tenure (in months)]:[Tenure (in months)]]/12} -> 1.2982391 | L35: {=D20*Dynamic_Row_Table[[Funding Rate]:[Funding Rate]]*Dynamic_Row_Table[[Tenure (in months)]:[Tenure (in months)]]/12} -> 1.6125496 | M35: {=E20*Dynamic_Row_Table[[Funding Rate]:[Funding Rate]]*Dynamic_Row_Table[[Tenure (in months)]:[Tenure (in months)]]/12} -> 2.1591766 | N35: {=F20*Dynamic_Row_Table[[Funding Rate]:[Funding Rate]]*Dynamic_Row_Table[[Tenure (in months)]:[Tenure (in months)]]/12} -> 3.0064484 | O35: {=G20*Dynamic_Row_Table[[Funding Rate]:[Funding Rate]]*Dynamic_Row_Table[[Tenure (in months)]:[Tenure (in months)]]/12} -> 3.9630456
A36: Millenial | B36: <50,000 | C36: =C21*'Portfolio x PD x Loan Count'!C135*'User Segmentation'!$I$49/'Portfolio x PD x Loan Count'!C67 -> 48.007024 | D36: =D21*'Portfolio x PD x Loan Count'!D135*'User Segmentation'!$I$49/'Portfolio x PD x Loan Count'!D67 -> 20.84955 | E36: =E21*'Portfolio x PD x Loan Count'!E135*'User Segmentation'!$I$49/'Portfolio x PD x Loan Count'!E67 -> 28.989689 | F36: =F21*'Portfolio x PD x Loan Count'!F135*'User Segmentation'!$I$49/'Portfolio x PD x Loan Count'!F67 -> 35.269407 | G36: =G21*'Portfolio x PD x Loan Count'!G135*'User Segmentation'!$I$49/'Portfolio x PD x Loan Count'!G67 -> 37.300257 | I36: Millenial | J36: <50,000 | K36: {=C21*Dynamic_Row_Table[[Funding Rate]:[Funding Rate]]*Dynamic_Row_Table[[Tenure (in months)]:[Tenure (in months)]]/12} -> 0.8669504 | L36: {=D21*Dynamic_Row_Table[[Funding Rate]:[Funding Rate]]*Dynamic_Row_Table[[Tenure (in months)]:[Tenure (in months)]]/12} -> 1.0526669 | M36: {=E21*Dynamic_Row_Table[[Funding Rate]:[Funding Rate]]*Dynamic_Row_Table[[Tenure (in months)]:[Tenure (in months)]]/12} -> 1.4242366 | N36: {=F21*Dynamic_Row_Table[[Funding Rate]:[Funding Rate]]*Dynamic_Row_Table[[Tenure (in months)]:[Tenure (in months)]]/12} -> 1.8577118 | O36: {=G21*Dynamic_Row_Table[[Funding Rate]:[Funding Rate]]*Dynamic_Row_Table[[Tenure (in months)]:[Tenure (in months)]]/12} -> 2.2958333
A37: Millenial | B37: 50,000-1,00,000 | C37: =C22*'Portfolio x PD x Loan Count'!C136*'User Segmentation'!$I$49/'Portfolio x PD x Loan Count'!C68 -> 65.146984 | D37: =D22*'Portfolio x PD x Loan Count'!D136*'User Segmentation'!$I$49/'Portfolio x PD x Loan Count'!D68 -> 30.661262 | E37: =E22*'Portfolio x PD x Loan Count'!E136*'User Segmentation'!$I$49/'Portfolio x PD x Loan Count'!E68 -> 45.376012 | F37: =F22*'Portfolio x PD x Loan Count'!F136*'User Segmentation'!$I$49/'Portfolio x PD x Loan Count'!F68 -> 56.559738 | G37: =G22*'Portfolio x PD x Loan Count'!G136*'User Segmentation'!$I$49/'Portfolio x PD x Loan Count'!G68 -> 64.831399 | I37: Millenial | J37: 50,000-1,00,000 | K37: {=C22*Dynamic_Row_Table[[Funding Rate]:[Funding Rate]]*Dynamic_Row_Table[[Tenure (in months)]:[Tenure (in months)]]/12} -> 1.1764779 | L37: {=D22*Dynamic_Row_Table[[Funding Rate]:[Funding Rate]]*Dynamic_Row_Table[[Tenure (in months)]:[Tenure (in months)]]/12} -> 1.5480476 | M37: {=E22*Dynamic_Row_Table[[Funding Rate]:[Funding Rate]]*Dynamic_Row_Table[[Tenure (in months)]:[Tenure (in months)]]/12} -> 2.2292815 | N37: {=F22*Dynamic_Row_Table[[Funding Rate]:[Funding Rate]]*Dynamic_Row_Table[[Tenure (in months)]:[Tenure (in months)]]/12} -> 2.9791171 | O37: {=G22*Dynamic_Row_Table[[Funding Rate]:[Funding Rate]]*Dynamic_Row_Table[[Tenure (in months)]:[Tenure (in months)]]/12} -> 3.990377
A38: Millenial | B38: >1,00,000 | C38: =C23*'Portfolio x PD x Loan Count'!C137*'User Segmentation'!$I$49/'Portfolio x PD x Loan Count'!C69 -> 99.88851 | D38: =D23*'Portfolio x PD x Loan Count'!D137*'User Segmentation'!$I$49/'Portfolio x PD x Loan Count'!D69 -> 49.261562 | E38: =E23*'Portfolio x PD x Loan Count'!E137*'User Segmentation'!$I$49/'Portfolio x PD x Loan Count'!E69 -> 73.712028 | F38: =F23*'Portfolio x PD x Loan Count'!F137*'User Segmentation'!$I$49/'Portfolio x PD x Loan Count'!F69 -> 87.693539 | G38: =G23*'Portfolio x PD x Loan Count'!G137*'User Segmentation'!$I$49/'Portfolio x PD x Loan Count'!G69 -> 87.700009 | I38: Millenial | J38: >1,00,000 | K38: {=C23*Dynamic_Row_Table[[Funding Rate]:[Funding Rate]]*Dynamic_Row_Table[[Tenure (in months)]:[Tenure (in months)]]/12} -> 1.803869 | L38: {=D23*Dynamic_Row_Table[[Funding Rate]:[Funding Rate]]*Dynamic_Row_Table[[Tenure (in months)]:[Tenure (in months)]]/12} -> 2.4871528 | M38: {=E23*Dynamic_Row_Table[[Funding Rate]:[Funding Rate]]*Dynamic_Row_Table[[Tenure (in months)]:[Tenure (in months)]]/12} -> 3.6214038 | N38: {=F23*Dynamic_Row_Table[[Funding Rate]:[Funding Rate]]*Dynamic_Row_Table[[Tenure (in months)]:[Tenure (in months)]]/12} -> 4.618998 | O38: {=G23*Dynamic_Row_Table[[Funding Rate]:[Funding Rate]]*Dynamic_Row_Table[[Tenure (in months)]:[Tenure (in months)]]/12} -> 5.3979415
A39: Gen X | B39: <50,000 | C39: =C24*'Portfolio x PD x Loan Count'!C138*'User Segmentation'!$I$49/'Portfolio x PD x Loan Count'!C70 -> 51.435016 | D39: =D24*'Portfolio x PD x Loan Count'!D138*'User Segmentation'!$I$49/'Portfolio x PD x Loan Count'!D70 -> 22.075676 | E39: =E24*'Portfolio x PD x Loan Count'!E138*'User Segmentation'!$I$49/'Portfolio x PD x Loan Count'!E70 -> 30.249747 | F39: =F24*'Portfolio x PD x Loan Count'!F138*'User Segmentation'!$I$49/'Portfolio x PD x Loan Count'!F70 -> 36.444708 | G39: =G24*'Portfolio x PD x Loan Count'!G138*'User Segmentation'!$I$49/'Portfolio x PD x Loan Count'!G70 -> 37.224768 | I39: Gen X | J39: <50,000 | K39: {=C24*Dynamic_Row_Table[[Funding Rate]:[Funding Rate]]*Dynamic_Row_Table[[Tenure (in months)]:[Tenure (in months)]]/12} -> 0.9288559 | L39: {=D24*Dynamic_Row_Table[[Funding Rate]:[Funding Rate]]*Dynamic_Row_Table[[Tenure (in months)]:[Tenure (in months)]]/12} -> 1.1145724 | M39: {=E24*Dynamic_Row_Table[[Funding Rate]:[Funding Rate]]*Dynamic_Row_Table[[Tenure (in months)]:[Tenure (in months)]]/12} -> 1.4861421 | N39: {=F24*Dynamic_Row_Table[[Funding Rate]:[Funding Rate]]*Dynamic_Row_Table[[Tenure (in months)]:[Tenure (in months)]]/12} -> 1.9196173 | O39: {=G24*Dynamic_Row_Table[[Funding Rate]:[Funding Rate]]*Dynamic_Row_Table[[Tenure (in months)]:[Tenure (in months)]]/12} -> 2.291187
A40: Gen X | B40: 50,000-1,00,000 | C40: =C25*'Portfolio x PD x Loan Count'!C139*'User Segmentation'!$I$49/'Portfolio x PD x Loan Count'!C71 -> 75.438527 | D40: =D25*'Portfolio x PD x Loan Count'!D139*'User Segmentation'!$I$49/'Portfolio x PD x Loan Count'!D71 -> 36.794598 | E40: =E25*'Portfolio x PD x Loan Count'!E139*'User Segmentation'!$I$49/'Portfolio x PD x Loan Count'!E71 -> 55.459261 | F40: =F25*'Portfolio x PD x Loan Count'!F139*'User Segmentation'!$I$49/'Portfolio x PD x Loan Count'!F71 -> 71.348293 | G40: =G25*'Portfolio x PD x Loan Count'!G139*'User Segmentation'!$I$49/'Portfolio x PD x Loan Count'!G71 -> 79.929122 | I40: Gen X | J40: 50,000-1,00,000 | K40: {=C25*Dynamic_Row_Table[[Funding Rate]:[Funding Rate]]*Dynamic_Row_Table[[Tenure (in months)]:[Tenure (in months)]]/12} -> 1.3623311 | L40: {=D25*Dynamic_Row_Table[[Funding Rate]:[Funding Rate]]*Dynamic_Row_Table[[Tenure (in months)]:[Tenure (in months)]]/12} -> 1.8577118 | M40: {=E25*Dynamic_Row_Table[[Funding Rate]:[Funding Rate]]*Dynamic_Row_Table[[Tenure (in months)]:[Tenure (in months)]]/12} -> 2.7246622 | N40: {=F25*Dynamic_Row_Table[[Funding Rate]:[Funding Rate]]*Dynamic_Row_Table[[Tenure (in months)]:[Tenure (in months)]]/12} -> 3.7580605 | O40: {=G25*Dynamic_Row_Table[[Funding Rate]:[Funding Rate]]*Dynamic_Row_Table[[Tenure (in months)]:[Tenure (in months)]]/12} -> 4.9196429
A41: Gen X | B41: >1,00,000 | C41: =C26*'Portfolio x PD x Loan Count'!C140*'User Segmentation'!$I$49/'Portfolio x PD x Loan Count'!C72 -> 119.56352 | D41: =D26*'Portfolio x PD x Loan Count'!D140*'User Segmentation'!$I$49/'Portfolio x PD x Loan Count'!D72 -> 60.629615 | E41: =E26*'Portfolio x PD x Loan Count'!E140*'User Segmentation'!$I$49/'Portfolio x PD x Loan Count'!E72 -> 91.23602 | F41: =F26*'Portfolio x PD x Loan Count'!F140*'User Segmentation'!$I$49/'Portfolio x PD x Loan Count'!F72 -> 95.476989 | G41: =G26*'Portfolio x PD x Loan Count'!G140*'User Segmentation'!$I$49/'Portfolio x PD x Loan Count'!G72 -> 87.700009 | I41: Gen X | J41: >1,00,000 | K41: {=C26*Dynamic_Row_Table[[Funding Rate]:[Funding Rate]]*Dynamic_Row_Table[[Tenure (in months)]:[Tenure (in months)]]/12} -> 2.1591766 | L41: {=D26*Dynamic_Row_Table[[Funding Rate]:[Funding Rate]]*Dynamic_Row_Table[[Tenure (in months)]:[Tenure (in months)]]/12} -> 3.0611111 | M41: {=E26*Dynamic_Row_Table[[Funding Rate]:[Funding Rate]]*Dynamic_Row_Table[[Tenure (in months)]:[Tenure (in months)]]/12} -> 4.4823413 | N41: {=F26*Dynamic_Row_Table[[Funding Rate]:[Funding Rate]]*Dynamic_Row_Table[[Tenure (in months)]:[Tenure (in months)]]/12} -> 5.0289683 | O41: {=G26*Dynamic_Row_Table[[Funding Rate]:[Funding Rate]]*Dynamic_Row_Table[[Tenure (in months)]:[Tenure (in months)]]/12} -> 5.3979415
A42: Baby Boomer | B42: <50,000 | C42: =C27*'Portfolio x PD x Loan Count'!C141*'User Segmentation'!$I$49/'Portfolio x PD x Loan Count'!C73 -> 41.151039 | D42: =D27*'Portfolio x PD x Loan Count'!D141*'User Segmentation'!$I$49/'Portfolio x PD x Loan Count'!D73 -> 18.397299 | E42: =E27*'Portfolio x PD x Loan Count'!E141*'User Segmentation'!$I$49/'Portfolio x PD x Loan Count'!E73 -> 23.946674 | F42: =F27*'Portfolio x PD x Loan Count'!F141*'User Segmentation'!$I$49/'Portfolio x PD x Loan Count'!F73 -> 28.215007 | G42: =G27*'Portfolio x PD x Loan Count'!G141*'User Segmentation'!$I$49/'Portfolio x PD x Loan Count'!G73 -> 30.182125 | I42: Baby Boomer | J42: <50,000 | K42: {=C27*Dynamic_Row_Table[[Funding Rate]:[Funding Rate]]*Dynamic_Row_Table[[Tenure (in months)]:[Tenure (in months)]]/12} -> 0.74313938 | L42: {=D27*Dynamic_Row_Table[[Funding Rate]:[Funding Rate]]*Dynamic_Row_Table[[Tenure (in months)]:[Tenure (in months)]]/12} -> 0.9288559 | M42: {=E27*Dynamic_Row_Table[[Funding Rate]:[Funding Rate]]*Dynamic_Row_Table[[Tenure (in months)]:[Tenure (in months)]]/12} -> 1.1764779 | N42: {=F27*Dynamic_Row_Table[[Funding Rate]:[Funding Rate]]*Dynamic_Row_Table[[Tenure (in months)]:[Tenure (in months)]]/12} -> 1.4861421 | O42: {=G27*Dynamic_Row_Table[[Funding Rate]:[Funding Rate]]*Dynamic_Row_Table[[Tenure (in months)]:[Tenure (in months)]]/12} -> 1.8577118
...

Sheet EAD Estimate
A1: Credit Category | B1: P(0.75) | C1: P(0.5) | D1: P(0.25) | E1: EAD | F1: LGD
A2: Deep Subprime | B2: 0.65 | C2: 0.25 | D2: 0.1 | E2: =B2*0.75+C2*0.5+D2*0.25 -> 0.6375 | F2: 1
A3: Sub Prime | B3: 0.45 | C3: 0.35 | D3: 0.2 | E3: =B3*0.75+C3*0.5+D3*0.25 -> 0.5625 | F3: 1
A4: Near Prime | B4: 0.3 | C4: 0.47 | D4: 0.23 | E4: =B4*0.75+C4*0.5+D4*0.25 -> 0.5175 | F4: 1
A5: Prime | B5: 0.25 | C5: 0.45 | D5: 0.3 | E5: =B5*0.75+C5*0.5+D5*0.25 -> 0.4875 | F5: 1
A6: Super Prime | B6: 0.15 | C6: 0.47 | D6: 0.38 | E6: =B6*0.75+C6*0.5+D6*0.25 -> 0.4425 | F6: 1

Sheet Dynamic PD
F1: Income Beta | G1: Beta Value | L1: {='Portfolio x PD x Loan Count'!A92:G105} -> Default Rate | M1: 0 | N1: 0 | O1: 0 | P1: 0 | Q1: 0 | R1: 0
F2: <50,000 | G2: 1.4 | L2: Generation | M2: Income Bracket | N2: Deep Subprime | O2: Sub Prime | P2: Near Prime | Q2: Prime | R2: Super Prime
F3: 50,000-1,00,000 | G3: 1.2 | L3: Gen Z | M3: <50,000 | N3: 0.0385 | O3: 0.0121 | P3: 0.0088 | Q3: 0.0077 | R3: 0.0088
F4: >1,00,000 | G4: 1.05 | L4: Gen Z | M4: 50,000-1,00,000 | N4: 0.0378 | O4: 0.01188 | P4: 0.00864 | Q4: 0.00756 | R4: 0.00864
L5: Gen Z | M5: >1,00,000 | N5: 0.035 | O5: 0.011 | P5: 0.008 | Q5: 0.007 | R5: 0.008
F6: Credit Category Beta | G6: Beta Value | L6: Millenial | M6: <50,000 | N6: 0.0385 | O6: 0.0121 | P6: 0.0088 | Q6: 0.0077 | R6: 0.0088
F7: Deep Subprime | G7: 1.35 | L7: Millenial | M7: 50,000-1,00,000 | N7: 0.0364 | O7: 0.01144 | P7: 0.00832 | Q7: 0.00728 | R7: 0.00832
F8: Sub Prime | G8: 1.2 | L8: Millenial | M8: >1,00,000 | N8: 0.035 | O8: 0.011 | P8: 0.008 | Q8: 0.007 | R8: 0.008
F9: Near Prime | G9: 1.1 | L9: Gen X | M9: <50,000 | N9: 0.035 | O9: 0.011 | P9: 0.008 | Q9: 0.007 | R9: 0.008
F10: Prime | G10: 1.05 | L10: Gen X | M10: 50,000-1,00,000 | N10: 0.035 | O10: 0.011 | P10: 0.008 | Q10: 0.007 | R10: 0.008
F11: Super Prime | G11: 1.02 | L11: Gen X | M11: >1,00,000 | N11: 0.035 | O11: 0.011 | P11: 0.008 | Q11: 0.007 | R11: 0.008
L12: Baby Boomer | M12: <50,000 | N12: 0.03675 | O12: 0.01155 | P12: 0.0084 | Q12: 0.00735 | R12: 0.0084
F13: Beta Segment | G13: LGD | H13: Fixed Cost | I13: Funding Rate | J13: Tenure (in months) | L13: Baby Boomer | M13: 50,000-1,00,000 | N13: 0.035 | O13: 0.011 | P13: 0.008 | Q13: 0.007 | R13: 0.008
F14: =(VLOOKUP($G$17,Beta_Income[#All],2,0))*(VLOOKUP($H$17,Beta_Credit[#All],2,0)) -> 1.32 | H14: 3 | I14: =(9.5% +Dashboard!$Q$25/10000) -> 0.095 | J14: 1.5 | L14: Baby Boomer | M14: >1,00,000 | N14: 0.035 | O14: 0.011 | P14: 0.008 | Q14: 0.007 | R14: 0.008
F16: Generation | G16: Income | H16: Credit Category | J16: Ticket Size | L16: PD(0)
F17: Gen Z | G17: 50,000-1,00,000 | H17: Near Prime | I17: 0 | J17: {=Table69[[ATS]:[ATS]]*(1+$I$17)} -> 125.14881 | L17: {=INDEX($N$3:$R$14, MATCH(1,($L$3:$L$14=$F$17)*($M$3:$M$14=$G$17),0), MATCH($H$17,$N$2:$R$2,0))} -> 0.00864
F19: PD(T) | L19: {='Support Tables'!A16:G29} -> Average Ticket Size | M19: 0 | N19: 0 | O19: 0 | P19: 0 | Q19: 0 | R19: 0
F20: {=IF($J$17<Table69[ATS],Table68[PD(0)],Table68[PD(0)]*($J$17/Table69[ATS])^Dynamic_Row_Table[Beta Segment])} -> 0.00864 | L20: Generation | M20: Income Bracket | N20: Deep Subprime | O20: Sub Prime | P20: Near Prime | Q20: Prime | R20: Super Prime
L21: Gen Z | M21: <50,000 | N21: 57.355556 | O21: 67.793254 | P21: 88.645635 | Q21: 114.72262 | R21: 151.22579
L22: Gen Z | M22: 50,000-1,00,000 | N22: 83.43254 | O22: 99.071825 | P22: 125.14881 | Q22: 166.86508 | R22: 212.89683
L23: Gen Z | M23: >1,00,000 | N23: 109.3254 | O23: 135.79365 | P23: 181.8254 | Q23: 253.1746 | R23: 333.73016
L24: Millenial | M24: <50,000 | N24: 73.006349 | O24: 88.645635 | P24: 119.93571 | Q24: 156.43889 | R24: 193.33333
L25: Millenial | M25: 50,000-1,00,000 | N25: 99.071825 | O25: 130.3619 | P25: 187.72897 | Q25: 250.87302 | R25: 336.03175
L26: Millenial | M26: >1,00,000 | N26: 151.90476 | O26: 209.44444 | P26: 304.96032 | Q26: 388.96825 | R26: 454.56349
L27: Gen X | M27: <50,000 | N27: 78.219444 | O27: 93.85873 | P27: 125.14881 | Q27: 161.65198 | R27: 192.94206
L28: Gen X | M28: 50,000-1,00,000 | N28: 114.72262 | O28: 156.43889 | P28: 229.44524 | Q28: 316.46825 | R28: 414.28571
L29: Gen X | M29: >1,00,000 | N29: 181.8254 | O29: 257.77778 | P29: 377.46032 | Q29: 423.49206 | R29: 454.56349
L30: Baby Boomer | M30: <50,000 | N30: 62.580159 | O30: 78.219444 | P30: 99.071825 | Q30: 125.14881 | R30: 156.43889
L31: Baby Boomer | M31: 50,000-1,00,000 | N31: 93.85873 | O31: 119.93571 | P31: 166.86508 | Q31: 220.95238 | R31: 293.45238
L32: Baby Boomer | M32: >1,00,000 | N32: 142.69841 | O32: 193.33333 | P32: 281.94444 | Q32: 365.95238 | R32: 431.54762
L34: ATS
L35: {=INDEX($N$21:$R$32,MATCH(1,($L$21:$L$32=$F$17)*($M$21:$M$32=$G$17),0),MATCH($H$17,$N$20:$R$20,0))} -> 125.14881

Sheet Contribution Margin
A1: CM per Loan (in $)
A2: Generation | B2: Income Bracket | C2: Deep Subprime | D2: Sub Prime | E2: Near Prime | F2: Prime | G2: Super Prime | I2: Generation | J2: Income Bracket | K2: Deep Subprime | L2: Sub Prime | M2: Near Prime | N2: Prime | O2: Super Prime
A3: Gen Z | B3: <50,000 | C3: {='Support Tables'!K48-'Support Tables'!K33-'Support Tables'!K18-Dynamic_Row_Table[[Fixed Cost]:[Fixed Cost]]} -> -2.2210399 | D3: {='Support Tables'!L48-'Support Tables'!L33-'Support Tables'!L18-Dynamic_Row_Table[[Fixed Cost]:[Fixed Cost]]} -> -0.87680003 | E3: {='Support Tables'!M48-'Support Tables'!M33-'Support Tables'!M18-Dynamic_Row_Table[[Fixed Cost]:[Fixed Cost]]} -> -0.02407739 | F3: {='Support Tables'!N48-'Support Tables'!N33-'Support Tables'!N18-Dynamic_Row_Table[[Fixed Cost]:[Fixed Cost]]} -> 0.94315982 | G3: {='Support Tables'!O48-'Support Tables'!O33-'Support Tables'!O18-Dynamic_Row_Table[[Fixed Cost]:[Fixed Cost]]} -> 2.1766101 | I3: Gen Z | J3: <50,000 | K3: =IF(CMPerLoan[[#This Row],[Deep Subprime]]>0,1,0) -> 0 | L3: =IF(CMPerLoan[[#This Row],[Sub Prime]]>0,1,0) -> 0 | M3: =IF(CMPerLoan[[#This Row],[Near Prime]]>0,1,0) -> 0 | N3: =IF(CMPerLoan[[#This Row],[Prime]]>0,1,0) -> 1 | O3: =IF(CMPerLoan[[#This Row],[Super Prime]]>0,1,0) -> 1
A4: Gen Z | B4: 50,000-1,00,000 | C4: {='Support Tables'!K49-'Support Tables'!K34-'Support Tables'!K19-Dynamic_Row_Table[[Fixed Cost]:[Fixed Cost]]} -> -1.82965 | D4: {='Support Tables'!L49-'Support Tables'!L34-'Support Tables'!L19-Dynamic_Row_Table[[Fixed Cost]:[Fixed Cost]]} -> 0.11506587 | E4: {='Support Tables'!M49-'Support Tables'!M34-'Support Tables'!M19-Dynamic_Row_Table[[Fixed Cost]:[Fixed Cost]]} -> 1.211733 | F4: {='Support Tables'!N49-'Support Tables'!N34-'Support Tables'!N19-Dynamic_Row_Table[[Fixed Cost]:[Fixed Cost]]} -> 2.7467499 | G4: {='Support Tables'!O49-'Support Tables'!O34-'Support Tables'!O19-Dynamic_Row_Table[[Fixed Cost]:[Fixed Cost]]} -> 4.3027443 | I4: Gen Z | J4: 50,000-1,00,000 | K4: =IF(CMPerLoan[[#This Row],[Deep Subprime]]>0,1,0) -> 0 | L4: =IF(CMPerLoan[[#This Row],[Sub Prime]]>0,1,0) -> 1 | M4: =IF(CMPerLoan[[#This Row],[Near Prime]]>0,1,0) -> 1 | N4: =IF(CMPerLoan[[#This Row],[Prime]]>0,1,0) -> 1 | O4: =IF(CMPerLoan[[#This Row],[Super Prime]]>0,1,0) -> 1
A5: Gen Z | B5: >1,00,000 | C5: {='Support Tables'!K50-'Support Tables'!K35-'Support Tables'!K20-Dynamic_Row_Table[[Fixed Cost]:[Fixed Cost]]} -> -1.2712922 | D5: {='Support Tables'!L50-'Support Tables'!L35-'Support Tables'!L20-Dynamic_Row_Table[[Fixed Cost]:[Fixed Cost]]} -> 1.3369097 | E5: {='Support Tables'!M50-'Support Tables'!M35-'Support Tables'!M20-Dynamic_Row_Table[[Fixed Cost]:[Fixed Cost]]} -> 3.1793361 | F5: {='Support Tables'!N50-'Support Tables'!N35-'Support Tables'!N20-Dynamic_Row_Table[[Fixed Cost]:[Fixed Cost]]} -> 5.7883234 | G5: {='Support Tables'!O50-'Support Tables'!O35-'Support Tables'!O20-Dynamic_Row_Table[[Fixed Cost]:[Fixed Cost]]} -> 8.5420575 | I5: Gen Z | J5: >1,00,000 | K5: =IF(CMPerLoan[[#This Row],[Deep Subprime]]>0,1,0) -> 0 | L5: =IF(CMPerLoan[[#This Row],[Sub Prime]]>0,1,0) -> 1 | M5: =IF(CMPerLoan[[#This Row],[Near Prime]]>0,1,0) -> 1 | N5: =IF(CMPerLoan[[#This Row],[Prime]]>0,1,0) -> 1 | O5: =IF(CMPerLoan[[#This Row],[Super Prime]]>0,1,0) -> 1
A6: Millenial | B6: <50,000 | C6: {='Support Tables'!K51-'Support Tables'!K36-'Support Tables'!K21-Dynamic_Row_Table[[Fixed Cost]:[Fixed Cost]]} -> -2.0084825 | D6: {='Support Tables'!L51-'Support Tables'!L36-'Support Tables'!L21-Dynamic_Row_Table[[Fixed Cost]:[Fixed Cost]]} -> -0.22372952 | E6: {='Support Tables'!M51-'Support Tables'!M36-'Support Tables'!M21-Dynamic_Row_Table[[Fixed Cost]:[Fixed Cost]]} -> 1.0263619 | F6: {='Support Tables'!N51-'Support Tables'!N36-'Support Tables'!N21-Dynamic_Row_Table[[Fixed Cost]:[Fixed Cost]]} -> 2.3770002 | G6: {='Support Tables'!O51-'Support Tables'!O36-'Support Tables'!O21-Dynamic_Row_Table[[Fixed Cost]:[Fixed Cost]]} -> 3.6179933 | I6: Millenial | J6: <50,000 | K6: =IF(CMPerLoan[[#This Row],[Deep Subprime]]>0,1,0) -> 0 | L6: =IF(CMPerLoan[[#This Row],[Sub Prime]]>0,1,0) -> 0 | M6: =IF(CMPerLoan[[#This Row],[Near Prime]]>0,1,0) -> 1 | N6: =IF(CMPerLoan[[#This Row],[Prime]]>0,1,0) -> 1 | O6: =IF(CMPerLoan[[#This Row],[Super Prime]]>0,1,0) -> 1
A7: Millenial | B7: 50,000-1,00,000 | C7: {='Support Tables'!K52-'Support Tables'!K37-'Support Tables'!K22-Dynamic_Row_Table[[Fixed Cost]:[Fixed Cost]]} -> -1.5218484 | D7: {='Support Tables'!L52-'Support Tables'!L37-'Support Tables'!L22-Dynamic_Row_Table[[Fixed Cost]:[Fixed Cost]]} -> 1.1311688 | E7: {='Support Tables'!M52-'Support Tables'!M37-'Support Tables'!M22-Dynamic_Row_Table[[Fixed Cost]:[Fixed Cost]]} -> 3.3488811 | F7: {='Support Tables'!N52-'Support Tables'!N37-'Support Tables'!N22-Dynamic_Row_Table[[Fixed Cost]:[Fixed Cost]]} -> 5.6741854 | G7: {='Support Tables'!O52-'Support Tables'!O37-'Support Tables'!O22-Dynamic_Row_Table[[Fixed Cost]:[Fixed Cost]]} -> 8.5740758 | I7: Millenial | J7: 50,000-1,00,000 | K7: =IF(CMPerLoan[[#This Row],[Deep Subprime]]>0,1,0) -> 0 | L7: =IF(CMPerLoan[[#This Row],[Sub Prime]]>0,1,0) -> 1 | M7: =IF(CMPerLoan[[#This Row],[Near Prime]]>0,1,0) -> 1 | N7: =IF(CMPerLoan[[#This Row],[Prime]]>0,1,0) -> 1 | O7: =IF(CMPerLoan[[#This Row],[Super Prime]]>0,1,0) -> 1
A8: Millenial | B8: >1,00,000 | C8: {='Support Tables'!K53-'Support Tables'!K38-'Support Tables'!K23-Dynamic_Row_Table[[Fixed Cost]:[Fixed Cost]]} -> -0.59800595 | D8: {='Support Tables'!L53-'Support Tables'!L38-'Support Tables'!L23-Dynamic_Row_Table[[Fixed Cost]:[Fixed Cost]]} -> 3.6891319 | E8: {='Support Tables'!M53-'Support Tables'!M38-'Support Tables'!M23-Dynamic_Row_Table[[Fixed Cost]:[Fixed Cost]]} -> 7.3640764 | F8: {='Support Tables'!N53-'Support Tables'!N38-'Support Tables'!N23-Dynamic_Row_Table[[Fixed Cost]:[Fixed Cost]]} -> 10.502061 | G8: {='Support Tables'!O53-'Support Tables'!O38-'Support Tables'!O23-Dynamic_Row_Table[[Fixed Cost]:[Fixed Cost]]} -> 12.721078 | I8: Millenial | J8: >1,00,000 | K8: =IF(CMPerLoan[[#This Row],[Deep Subprime]]>0,1,0) -> 0 | L8: =IF(CMPerLoan[[#This Row],[Sub Prime]]>0,1,0) -> 1 | M8: =IF(CMPerLoan[[#This Row],[Near Prime]]>0,1,0) -> 1 | N8: =IF(CMPerLoan[[#This Row],[Prime]]>0,1,0) -> 1 | O8: =IF(CMPerLoan[[#This Row],[Super Prime]]>0,1,0) -> 1
A9: Gen X | B9: <50,000 | C9: {='Support Tables'!K54-'Support Tables'!K39-'Support Tables'!K24-Dynamic_Row_Table[[Fixed Cost]:[Fixed Cost]]} -> -1.763155 | D9: {='Support Tables'!L54-'Support Tables'!L39-'Support Tables'!L24-Dynamic_Row_Table[[Fixed Cost]:[Fixed Cost]]} -> -0.0023868056 | E9: {='Support Tables'!M54-'Support Tables'!M39-'Support Tables'!M24-Dynamic_Row_Table[[Fixed Cost]:[Fixed Cost]]} -> 1.2531823 | F9: {='Support Tables'!N54-'Support Tables'!N39-'Support Tables'!N24-Dynamic_Row_Table[[Fixed Cost]:[Fixed Cost]]} -> 2.6113445 | G9: {='Support Tables'!O54-'Support Tables'!O39-'Support Tables'!O24-Dynamic_Row_Table[[Fixed Cost]:[Fixed Cost]]} -> 3.6729013 | I9: Gen X | J9: <50,000 | K9: =IF(CMPerLoan[[#This Row],[Deep Subprime]]>0,1,0) -> 0 | L9: =IF(CMPerLoan[[#This Row],[Sub Prime]]>0,1,0) -> 0 | M9: =IF(CMPerLoan[[#This Row],[Near Prime]]>0,1,0) -> 1 | N9: =IF(CMPerLoan[[#This Row],[Prime]]>0,1,0) -> 1 | O9: =IF(CMPerLoan[[#This Row],[Super Prime]]>0,1,0) -> 1
A10: Gen X | B10: 50,000-1,00,000 | C10: {='Support Tables'!K55-'Support Tables'!K40-'Support Tables'!K25-Dynamic_Row_Table[[Fixed Cost]:[Fixed Cost]]} -> -1.1859486 | D10: {='Support Tables'!L55-'Support Tables'!L40-'Support Tables'!L25-Dynamic_Row_Table[[Fixed Cost]:[Fixed Cost]]} -> 1.996267 | E10: {='Support Tables'!M55-'Support Tables'!M40-'Support Tables'!M25-Dynamic_Row_Table[[Fixed Cost]:[Fixed Cost]]} -> 4.7976964 | F10: {='Support Tables'!N55-'Support Tables'!N40-'Support Tables'!N25-Dynamic_Row_Table[[Fixed Cost]:[Fixed Cost]]} -> 7.9854043 | G10: {='Support Tables'!O55-'Support Tables'!O40-'Support Tables'!O25-Dynamic_Row_Table[[Fixed Cost]:[Fixed Cost]]} -> 11.328071 | I10: Gen X | J10: 50,000-1,00,000 | K10: =IF(CMPerLoan[[#This Row],[Deep Subprime]]>0,1,0) -> 0 | L10: =IF(CMPerLoan[[#This Row],[Sub Prime]]>0,1,0) -> 1 | M10: =IF(CMPerLoan[[#This Row],[Near Prime]]>0,1,0) -> 1 | N10: =IF(CMPerLoan[[#This Row],[Prime]]>0,1,0) -> 1 | O10: =IF(CMPerLoan[[#This Row],[Super Prime]]>0,1,0) -> 1
